/home/ammadkhalid/projects/python/clients/autobots/google-bank-adder/gbank/core/decorator.py: ERROR    HTTPConnectionPool(host='127.0.0.1', port=57701): Max retries exceeded with url: /session/87c38b6a3612aac8c8f04aedf6c6411d/screenshot (Caused by NewConnectionError('<urllib3.connection.HTTPConnection object at 0x7f5c5f7b1160>: Failed to establish a new connection: [Errno 111] Connection refused',))
Traceback (most recent call last):
  File "/home/ammadkhalid/projects/python/clients/autobots/google-bank-adder/gbank/core/decorator.py", line 43, in wrap
    return obj(*args, **kwargs)
  File "/home/ammadkhalid/projects/python/clients/autobots/google-bank-adder/gbank/bot/google.py", line 289, in go_to_bank
    self.add_bank()
  File "/home/ammadkhalid/projects/python/clients/autobots/google-bank-adder/gbank/core/decorator.py", line 56, in wrap
    raise e
  File "/home/ammadkhalid/projects/python/clients/autobots/google-bank-adder/gbank/core/decorator.py", line 43, in wrap
    return obj(*args, **kwargs)
  File "/home/ammadkhalid/projects/python/clients/autobots/google-bank-adder/gbank/bot/google.py", line 234, in add_bank
    By.ID, path
  File "/home/ammadkhalid/projects/python/me/am-py-bot/venv/lib/python3.6/site-packages/selenium/webdriver/support/wait.py", line 80, in until
    raise TimeoutException(message, screen, stacktrace)
selenium.common.exceptions.TimeoutException: Message:  Screenshot: /home/ammadkhalid/projects/python/clients/autobots/google-bank-adder/logs/screenshots/screenshot_20190105-180027.png


During handling of the above exception, another exception occurred:

Traceback (most recent call last):
  File "/home/ammadkhalid/projects/python/me/am-py-bot/venv/lib/python3.6/site-packages/urllib3/connection.py", line 159, in _new_conn
    (self._dns_host, self.port), self.timeout, **extra_kw)
  File "/home/ammadkhalid/projects/python/me/am-py-bot/venv/lib/python3.6/site-packages/urllib3/util/connection.py", line 80, in create_connection
    raise err
  File "/home/ammadkhalid/projects/python/me/am-py-bot/venv/lib/python3.6/site-packages/urllib3/util/connection.py", line 70, in create_connection
    sock.connect(sa)
ConnectionRefusedError: [Errno 111] Connection refused

During handling of the above exception, another exception occurred:

Traceback (most recent call last):
  File "/home/ammadkhalid/projects/python/me/am-py-bot/venv/lib/python3.6/site-packages/urllib3/connectionpool.py", line 600, in urlopen
    chunked=chunked)
  File "/home/ammadkhalid/projects/python/me/am-py-bot/venv/lib/python3.6/site-packages/urllib3/connectionpool.py", line 354, in _make_request
    conn.request(method, url, **httplib_request_kw)
  File "/usr/lib/python3.6/http/client.py", line 1239, in request
    self._send_request(method, url, body, headers, encode_chunked)
  File "/usr/lib/python3.6/http/client.py", line 1285, in _send_request
    self.endheaders(body, encode_chunked=encode_chunked)
  File "/usr/lib/python3.6/http/client.py", line 1234, in endheaders
    self._send_output(message_body, encode_chunked=encode_chunked)
  File "/usr/lib/python3.6/http/client.py", line 1026, in _send_output
    self.send(msg)
  File "/usr/lib/python3.6/http/client.py", line 964, in send
    self.connect()
  File "/home/ammadkhalid/projects/python/me/am-py-bot/venv/lib/python3.6/site-packages/urllib3/connection.py", line 181, in connect
    conn = self._new_conn()
  File "/home/ammadkhalid/projects/python/me/am-py-bot/venv/lib/python3.6/site-packages/urllib3/connection.py", line 168, in _new_conn
    self, "Failed to establish a new connection: %s" % e)
urllib3.exceptions.NewConnectionError: <urllib3.connection.HTTPConnection object at 0x7f5c5f7b1160>: Failed to establish a new connection: [Errno 111] Connection refused

During handling of the above exception, another exception occurred:

Traceback (most recent call last):
  File "/home/ammadkhalid/projects/python/clients/autobots/google-bank-adder/gbank/core/decorator.py", line 26, in wrap
    return func(*args, **kwargs)
  File "/home/ammadkhalid/projects/python/clients/autobots/google-bank-adder/gbank/cli/main.py", line 22, in main
    CommandLine().run()
  File "/home/ammadkhalid/projects/python/clients/autobots/google-bank-adder/gbank/cli/main.py", line 14, in run
    self.arg_parser.parse_args()
  File "/home/ammadkhalid/projects/python/clients/autobots/google-bank-adder/gbank/core/argparser.py", line 89, in parse_args
    self._run_program(fun, args)
  File "/home/ammadkhalid/projects/python/clients/autobots/google-bank-adder/gbank/core/argparser.py", line 79, in _run_program
    self._out = fun(**kwargs)
  File "/home/ammadkhalid/projects/python/clients/autobots/google-bank-adder/gbank/cli/google.py", line 17, in main
    driver.go_to_bank()
  File "/home/ammadkhalid/projects/python/clients/autobots/google-bank-adder/gbank/core/decorator.py", line 50, in wrap
    path = take_screenshot(driver)
  File "/home/ammadkhalid/projects/python/clients/autobots/google-bank-adder/gbank/helper.py", line 179, in take_screenshot
    bot.get_driver().save_screenshot(path)
  File "/home/ammadkhalid/projects/python/me/am-py-bot/venv/lib/python3.6/site-packages/selenium/webdriver/remote/webdriver.py", line 1055, in save_screenshot
    return self.get_screenshot_as_file(filename)
  File "/home/ammadkhalid/projects/python/me/am-py-bot/venv/lib/python3.6/site-packages/selenium/webdriver/remote/webdriver.py", line 1032, in get_screenshot_as_file
    png = self.get_screenshot_as_png()
  File "/home/ammadkhalid/projects/python/me/am-py-bot/venv/lib/python3.6/site-packages/selenium/webdriver/remote/webdriver.py", line 1064, in get_screenshot_as_png
    return base64.b64decode(self.get_screenshot_as_base64().encode('ascii'))
  File "/home/ammadkhalid/projects/python/me/am-py-bot/venv/lib/python3.6/site-packages/selenium/webdriver/remote/webdriver.py", line 1074, in get_screenshot_as_base64
    return self.execute(Command.SCREENSHOT)['value']
  File "/home/ammadkhalid/projects/python/me/am-py-bot/venv/lib/python3.6/site-packages/selenium/webdriver/remote/webdriver.py", line 319, in execute
    response = self.command_executor.execute(driver_command, params)
  File "/home/ammadkhalid/projects/python/me/am-py-bot/venv/lib/python3.6/site-packages/selenium/webdriver/remote/remote_connection.py", line 374, in execute
    return self._request(command_info[0], url, body=data)
  File "/home/ammadkhalid/projects/python/me/am-py-bot/venv/lib/python3.6/site-packages/selenium/webdriver/remote/remote_connection.py", line 397, in _request
    resp = self._conn.request(method, url, body=body, headers=headers)
  File "/home/ammadkhalid/projects/python/me/am-py-bot/venv/lib/python3.6/site-packages/urllib3/request.py", line 68, in request
    **urlopen_kw)
  File "/home/ammadkhalid/projects/python/me/am-py-bot/venv/lib/python3.6/site-packages/urllib3/request.py", line 89, in request_encode_url
    return self.urlopen(method, url, **extra_kw)
  File "/home/ammadkhalid/projects/python/me/am-py-bot/venv/lib/python3.6/site-packages/urllib3/poolmanager.py", line 323, in urlopen
    response = conn.urlopen(method, u.request_uri, **kw)
  File "/home/ammadkhalid/projects/python/me/am-py-bot/venv/lib/python3.6/site-packages/urllib3/connectionpool.py", line 667, in urlopen
    **response_kw)
  File "/home/ammadkhalid/projects/python/me/am-py-bot/venv/lib/python3.6/site-packages/urllib3/connectionpool.py", line 667, in urlopen
    **response_kw)
  File "/home/ammadkhalid/projects/python/me/am-py-bot/venv/lib/python3.6/site-packages/urllib3/connectionpool.py", line 667, in urlopen
    **response_kw)
  File "/home/ammadkhalid/projects/python/me/am-py-bot/venv/lib/python3.6/site-packages/urllib3/connectionpool.py", line 638, in urlopen
    _stacktrace=sys.exc_info()[2])
  File "/home/ammadkhalid/projects/python/me/am-py-bot/venv/lib/python3.6/site-packages/urllib3/util/retry.py", line 398, in increment
    raise MaxRetryError(_pool, url, error or ResponseError(cause))
urllib3.exceptions.MaxRetryError: HTTPConnectionPool(host='127.0.0.1', port=57701): Max retries exceeded with url: /session/87c38b6a3612aac8c8f04aedf6c6411d/screenshot (Caused by NewConnectionError('<urllib3.connection.HTTPConnection object at 0x7f5c5f7b1160>: Failed to establish a new connection: [Errno 111] Connection refused',))
/home/ammadkhalid/projects/python/clients/autobots/google-bank-adder/gbank/core/decorator.py: ERROR    HTTPConnectionPool(host='127.0.0.1', port=43055): Max retries exceeded with url: /session/bd9e64c6dcb2ff601c77ce147225bbf5/screenshot (Caused by NewConnectionError('<urllib3.connection.HTTPConnection object at 0x7fc803230160>: Failed to establish a new connection: [Errno 111] Connection refused',))
Traceback (most recent call last):
  File "/home/ammadkhalid/projects/python/clients/autobots/google-bank-adder/gbank/core/decorator.py", line 58, in wrap
    return obj(*args, **kwargs)
  File "/home/ammadkhalid/projects/python/clients/autobots/google-bank-adder/gbank/bot/google.py", line 289, in go_to_bank
    self.add_bank()
  File "/home/ammadkhalid/projects/python/clients/autobots/google-bank-adder/gbank/core/decorator.py", line 71, in wrap
    raise e
  File "/home/ammadkhalid/projects/python/clients/autobots/google-bank-adder/gbank/core/decorator.py", line 58, in wrap
    return obj(*args, **kwargs)
  File "/home/ammadkhalid/projects/python/clients/autobots/google-bank-adder/gbank/bot/google.py", line 234, in add_bank
    By.ID, path
  File "/home/ammadkhalid/projects/python/me/am-py-bot/venv/lib/python3.6/site-packages/selenium/webdriver/support/wait.py", line 80, in until
    raise TimeoutException(message, screen, stacktrace)
selenium.common.exceptions.TimeoutException: Message:  Screenshot: /home/ammadkhalid/projects/python/clients/autobots/google-bank-adder/logs/screenshots/screenshot_20190105-181310.png


During handling of the above exception, another exception occurred:

Traceback (most recent call last):
  File "/home/ammadkhalid/projects/python/me/am-py-bot/venv/lib/python3.6/site-packages/urllib3/connection.py", line 159, in _new_conn
    (self._dns_host, self.port), self.timeout, **extra_kw)
  File "/home/ammadkhalid/projects/python/me/am-py-bot/venv/lib/python3.6/site-packages/urllib3/util/connection.py", line 80, in create_connection
    raise err
  File "/home/ammadkhalid/projects/python/me/am-py-bot/venv/lib/python3.6/site-packages/urllib3/util/connection.py", line 70, in create_connection
    sock.connect(sa)
ConnectionRefusedError: [Errno 111] Connection refused

During handling of the above exception, another exception occurred:

Traceback (most recent call last):
  File "/home/ammadkhalid/projects/python/me/am-py-bot/venv/lib/python3.6/site-packages/urllib3/connectionpool.py", line 600, in urlopen
    chunked=chunked)
  File "/home/ammadkhalid/projects/python/me/am-py-bot/venv/lib/python3.6/site-packages/urllib3/connectionpool.py", line 354, in _make_request
    conn.request(method, url, **httplib_request_kw)
  File "/usr/lib/python3.6/http/client.py", line 1239, in request
    self._send_request(method, url, body, headers, encode_chunked)
  File "/usr/lib/python3.6/http/client.py", line 1285, in _send_request
    self.endheaders(body, encode_chunked=encode_chunked)
  File "/usr/lib/python3.6/http/client.py", line 1234, in endheaders
    self._send_output(message_body, encode_chunked=encode_chunked)
  File "/usr/lib/python3.6/http/client.py", line 1026, in _send_output
    self.send(msg)
  File "/usr/lib/python3.6/http/client.py", line 964, in send
    self.connect()
  File "/home/ammadkhalid/projects/python/me/am-py-bot/venv/lib/python3.6/site-packages/urllib3/connection.py", line 181, in connect
    conn = self._new_conn()
  File "/home/ammadkhalid/projects/python/me/am-py-bot/venv/lib/python3.6/site-packages/urllib3/connection.py", line 168, in _new_conn
    self, "Failed to establish a new connection: %s" % e)
urllib3.exceptions.NewConnectionError: <urllib3.connection.HTTPConnection object at 0x7fc803230160>: Failed to establish a new connection: [Errno 111] Connection refused

During handling of the above exception, another exception occurred:

Traceback (most recent call last):
  File "/home/ammadkhalid/projects/python/clients/autobots/google-bank-adder/gbank/core/decorator.py", line 26, in wrap
    return func(*args, **kwargs)
  File "/home/ammadkhalid/projects/python/clients/autobots/google-bank-adder/gbank/cli/main.py", line 22, in main
    CommandLine().run()
  File "/home/ammadkhalid/projects/python/clients/autobots/google-bank-adder/gbank/cli/main.py", line 14, in run
    self.arg_parser.parse_args()
  File "/home/ammadkhalid/projects/python/clients/autobots/google-bank-adder/gbank/core/argparser.py", line 89, in parse_args
    self._run_program(fun, args)
  File "/home/ammadkhalid/projects/python/clients/autobots/google-bank-adder/gbank/core/argparser.py", line 79, in _run_program
    self._out = fun(**kwargs)
  File "/home/ammadkhalid/projects/python/clients/autobots/google-bank-adder/gbank/cli/google.py", line 21, in main
    driver.go_to_bank()
  File "/home/ammadkhalid/projects/python/clients/autobots/google-bank-adder/gbank/core/decorator.py", line 65, in wrap
    path = take_screenshot(driver)
  File "/home/ammadkhalid/projects/python/clients/autobots/google-bank-adder/gbank/helper.py", line 179, in take_screenshot
    bot.get_driver().save_screenshot(path)
  File "/home/ammadkhalid/projects/python/me/am-py-bot/venv/lib/python3.6/site-packages/selenium/webdriver/remote/webdriver.py", line 1055, in save_screenshot
    return self.get_screenshot_as_file(filename)
  File "/home/ammadkhalid/projects/python/me/am-py-bot/venv/lib/python3.6/site-packages/selenium/webdriver/remote/webdriver.py", line 1032, in get_screenshot_as_file
    png = self.get_screenshot_as_png()
  File "/home/ammadkhalid/projects/python/me/am-py-bot/venv/lib/python3.6/site-packages/selenium/webdriver/remote/webdriver.py", line 1064, in get_screenshot_as_png
    return base64.b64decode(self.get_screenshot_as_base64().encode('ascii'))
  File "/home/ammadkhalid/projects/python/me/am-py-bot/venv/lib/python3.6/site-packages/selenium/webdriver/remote/webdriver.py", line 1074, in get_screenshot_as_base64
    return self.execute(Command.SCREENSHOT)['value']
  File "/home/ammadkhalid/projects/python/me/am-py-bot/venv/lib/python3.6/site-packages/selenium/webdriver/remote/webdriver.py", line 319, in execute
    response = self.command_executor.execute(driver_command, params)
  File "/home/ammadkhalid/projects/python/me/am-py-bot/venv/lib/python3.6/site-packages/selenium/webdriver/remote/remote_connection.py", line 374, in execute
    return self._request(command_info[0], url, body=data)
  File "/home/ammadkhalid/projects/python/me/am-py-bot/venv/lib/python3.6/site-packages/selenium/webdriver/remote/remote_connection.py", line 397, in _request
    resp = self._conn.request(method, url, body=body, headers=headers)
  File "/home/ammadkhalid/projects/python/me/am-py-bot/venv/lib/python3.6/site-packages/urllib3/request.py", line 68, in request
    **urlopen_kw)
  File "/home/ammadkhalid/projects/python/me/am-py-bot/venv/lib/python3.6/site-packages/urllib3/request.py", line 89, in request_encode_url
    return self.urlopen(method, url, **extra_kw)
  File "/home/ammadkhalid/projects/python/me/am-py-bot/venv/lib/python3.6/site-packages/urllib3/poolmanager.py", line 323, in urlopen
    response = conn.urlopen(method, u.request_uri, **kw)
  File "/home/ammadkhalid/projects/python/me/am-py-bot/venv/lib/python3.6/site-packages/urllib3/connectionpool.py", line 667, in urlopen
    **response_kw)
  File "/home/ammadkhalid/projects/python/me/am-py-bot/venv/lib/python3.6/site-packages/urllib3/connectionpool.py", line 667, in urlopen
    **response_kw)
  File "/home/ammadkhalid/projects/python/me/am-py-bot/venv/lib/python3.6/site-packages/urllib3/connectionpool.py", line 667, in urlopen
    **response_kw)
  File "/home/ammadkhalid/projects/python/me/am-py-bot/venv/lib/python3.6/site-packages/urllib3/connectionpool.py", line 638, in urlopen
    _stacktrace=sys.exc_info()[2])
  File "/home/ammadkhalid/projects/python/me/am-py-bot/venv/lib/python3.6/site-packages/urllib3/util/retry.py", line 398, in increment
    raise MaxRetryError(_pool, url, error or ResponseError(cause))
urllib3.exceptions.MaxRetryError: HTTPConnectionPool(host='127.0.0.1', port=43055): Max retries exceeded with url: /session/bd9e64c6dcb2ff601c77ce147225bbf5/screenshot (Caused by NewConnectionError('<urllib3.connection.HTTPConnection object at 0x7fc803230160>: Failed to establish a new connection: [Errno 111] Connection refused',))
/home/ammadkhalid/projects/python/clients/autobots/google-bank-adder/gbank/core/decorator.py: ERROR    Message:  Screenshot: /home/ammadkhalid/projects/python/clients/autobots/google-bank-adder/logs/screenshots/screenshot_20190105-184640.png
Traceback (most recent call last):
  File "/home/ammadkhalid/projects/python/clients/autobots/google-bank-adder/gbank/core/decorator.py", line 38, in wrap
    return obj(*args, **kwargs)
  File "/home/ammadkhalid/projects/python/clients/autobots/google-bank-adder/gbank/bot/google.py", line 234, in add_bank
    By.ID, path
  File "/home/ammadkhalid/projects/python/me/am-py-bot/venv/lib/python3.6/site-packages/selenium/webdriver/support/wait.py", line 80, in until
    raise TimeoutException(message, screen, stacktrace)
selenium.common.exceptions.TimeoutException: Message:  Screenshot: /home/ammadkhalid/projects/python/clients/autobots/google-bank-adder/logs/screenshots/screenshot_20190105-184640.png

/home/ammadkhalid/projects/python/clients/autobots/google-bank-adder/gbank/core/decorator.py: ERROR    HTTPConnectionPool(host='127.0.0.1', port=59975): Max retries exceeded with url: /session/45d8afed6c5f7e4de7bb40ce9f2255d3/screenshot (Caused by NewConnectionError('<urllib3.connection.HTTPConnection object at 0x7f7c1279a908>: Failed to establish a new connection: [Errno 111] Connection refused',))
Traceback (most recent call last):
  File "/home/ammadkhalid/projects/python/clients/autobots/google-bank-adder/gbank/core/decorator.py", line 38, in wrap
    return obj(*args, **kwargs)
  File "/home/ammadkhalid/projects/python/clients/autobots/google-bank-adder/gbank/bot/google.py", line 289, in go_to_bank
    self.add_bank()
  File "/home/ammadkhalid/projects/python/clients/autobots/google-bank-adder/gbank/core/decorator.py", line 70, in wrap
    raise e
  File "/home/ammadkhalid/projects/python/clients/autobots/google-bank-adder/gbank/core/decorator.py", line 38, in wrap
    return obj(*args, **kwargs)
  File "/home/ammadkhalid/projects/python/clients/autobots/google-bank-adder/gbank/bot/google.py", line 234, in add_bank
    By.ID, path
  File "/home/ammadkhalid/projects/python/me/am-py-bot/venv/lib/python3.6/site-packages/selenium/webdriver/support/wait.py", line 80, in until
    raise TimeoutException(message, screen, stacktrace)
selenium.common.exceptions.TimeoutException: Message:  Screenshot: /home/ammadkhalid/projects/python/clients/autobots/google-bank-adder/logs/screenshots/screenshot_20190105-184640.png


During handling of the above exception, another exception occurred:

Traceback (most recent call last):
  File "/home/ammadkhalid/projects/python/me/am-py-bot/venv/lib/python3.6/site-packages/urllib3/connection.py", line 159, in _new_conn
    (self._dns_host, self.port), self.timeout, **extra_kw)
  File "/home/ammadkhalid/projects/python/me/am-py-bot/venv/lib/python3.6/site-packages/urllib3/util/connection.py", line 80, in create_connection
    raise err
  File "/home/ammadkhalid/projects/python/me/am-py-bot/venv/lib/python3.6/site-packages/urllib3/util/connection.py", line 70, in create_connection
    sock.connect(sa)
ConnectionRefusedError: [Errno 111] Connection refused

During handling of the above exception, another exception occurred:

Traceback (most recent call last):
  File "/home/ammadkhalid/projects/python/me/am-py-bot/venv/lib/python3.6/site-packages/urllib3/connectionpool.py", line 600, in urlopen
    chunked=chunked)
  File "/home/ammadkhalid/projects/python/me/am-py-bot/venv/lib/python3.6/site-packages/urllib3/connectionpool.py", line 354, in _make_request
    conn.request(method, url, **httplib_request_kw)
  File "/usr/lib/python3.6/http/client.py", line 1239, in request
    self._send_request(method, url, body, headers, encode_chunked)
  File "/usr/lib/python3.6/http/client.py", line 1285, in _send_request
    self.endheaders(body, encode_chunked=encode_chunked)
  File "/usr/lib/python3.6/http/client.py", line 1234, in endheaders
    self._send_output(message_body, encode_chunked=encode_chunked)
  File "/usr/lib/python3.6/http/client.py", line 1026, in _send_output
    self.send(msg)
  File "/usr/lib/python3.6/http/client.py", line 964, in send
    self.connect()
  File "/home/ammadkhalid/projects/python/me/am-py-bot/venv/lib/python3.6/site-packages/urllib3/connection.py", line 181, in connect
    conn = self._new_conn()
  File "/home/ammadkhalid/projects/python/me/am-py-bot/venv/lib/python3.6/site-packages/urllib3/connection.py", line 168, in _new_conn
    self, "Failed to establish a new connection: %s" % e)
urllib3.exceptions.NewConnectionError: <urllib3.connection.HTTPConnection object at 0x7f7c1279a908>: Failed to establish a new connection: [Errno 111] Connection refused

During handling of the above exception, another exception occurred:

Traceback (most recent call last):
  File "/home/ammadkhalid/projects/python/clients/autobots/google-bank-adder/gbank/core/decorator.py", line 26, in wrap
    return func(*args, **kwargs)
  File "/home/ammadkhalid/projects/python/clients/autobots/google-bank-adder/gbank/cli/main.py", line 22, in main
    CommandLine().run()
  File "/home/ammadkhalid/projects/python/clients/autobots/google-bank-adder/gbank/cli/main.py", line 14, in run
    self.arg_parser.parse_args()
  File "/home/ammadkhalid/projects/python/clients/autobots/google-bank-adder/gbank/core/argparser.py", line 89, in parse_args
    self._run_program(fun, args)
  File "/home/ammadkhalid/projects/python/clients/autobots/google-bank-adder/gbank/core/argparser.py", line 79, in _run_program
    self._out = fun(**kwargs)
  File "/home/ammadkhalid/projects/python/clients/autobots/google-bank-adder/gbank/cli/google.py", line 21, in main
    driver.go_to_bank()
  File "/home/ammadkhalid/projects/python/clients/autobots/google-bank-adder/gbank/core/decorator.py", line 45, in wrap
    path = take_screenshot(driver)
  File "/home/ammadkhalid/projects/python/clients/autobots/google-bank-adder/gbank/helper.py", line 179, in take_screenshot
    bot.get_driver().save_screenshot(path)
  File "/home/ammadkhalid/projects/python/me/am-py-bot/venv/lib/python3.6/site-packages/selenium/webdriver/remote/webdriver.py", line 1055, in save_screenshot
    return self.get_screenshot_as_file(filename)
  File "/home/ammadkhalid/projects/python/me/am-py-bot/venv/lib/python3.6/site-packages/selenium/webdriver/remote/webdriver.py", line 1032, in get_screenshot_as_file
    png = self.get_screenshot_as_png()
  File "/home/ammadkhalid/projects/python/me/am-py-bot/venv/lib/python3.6/site-packages/selenium/webdriver/remote/webdriver.py", line 1064, in get_screenshot_as_png
    return base64.b64decode(self.get_screenshot_as_base64().encode('ascii'))
  File "/home/ammadkhalid/projects/python/me/am-py-bot/venv/lib/python3.6/site-packages/selenium/webdriver/remote/webdriver.py", line 1074, in get_screenshot_as_base64
    return self.execute(Command.SCREENSHOT)['value']
  File "/home/ammadkhalid/projects/python/me/am-py-bot/venv/lib/python3.6/site-packages/selenium/webdriver/remote/webdriver.py", line 319, in execute
    response = self.command_executor.execute(driver_command, params)
  File "/home/ammadkhalid/projects/python/me/am-py-bot/venv/lib/python3.6/site-packages/selenium/webdriver/remote/remote_connection.py", line 374, in execute
    return self._request(command_info[0], url, body=data)
  File "/home/ammadkhalid/projects/python/me/am-py-bot/venv/lib/python3.6/site-packages/selenium/webdriver/remote/remote_connection.py", line 397, in _request
    resp = self._conn.request(method, url, body=body, headers=headers)
  File "/home/ammadkhalid/projects/python/me/am-py-bot/venv/lib/python3.6/site-packages/urllib3/request.py", line 68, in request
    **urlopen_kw)
  File "/home/ammadkhalid/projects/python/me/am-py-bot/venv/lib/python3.6/site-packages/urllib3/request.py", line 89, in request_encode_url
    return self.urlopen(method, url, **extra_kw)
  File "/home/ammadkhalid/projects/python/me/am-py-bot/venv/lib/python3.6/site-packages/urllib3/poolmanager.py", line 323, in urlopen
    response = conn.urlopen(method, u.request_uri, **kw)
  File "/home/ammadkhalid/projects/python/me/am-py-bot/venv/lib/python3.6/site-packages/urllib3/connectionpool.py", line 667, in urlopen
    **response_kw)
  File "/home/ammadkhalid/projects/python/me/am-py-bot/venv/lib/python3.6/site-packages/urllib3/connectionpool.py", line 667, in urlopen
    **response_kw)
  File "/home/ammadkhalid/projects/python/me/am-py-bot/venv/lib/python3.6/site-packages/urllib3/connectionpool.py", line 667, in urlopen
    **response_kw)
  File "/home/ammadkhalid/projects/python/me/am-py-bot/venv/lib/python3.6/site-packages/urllib3/connectionpool.py", line 638, in urlopen
    _stacktrace=sys.exc_info()[2])
  File "/home/ammadkhalid/projects/python/me/am-py-bot/venv/lib/python3.6/site-packages/urllib3/util/retry.py", line 398, in increment
    raise MaxRetryError(_pool, url, error or ResponseError(cause))
urllib3.exceptions.MaxRetryError: HTTPConnectionPool(host='127.0.0.1', port=59975): Max retries exceeded with url: /session/45d8afed6c5f7e4de7bb40ce9f2255d3/screenshot (Caused by NewConnectionError('<urllib3.connection.HTTPConnection object at 0x7f7c1279a908>: Failed to establish a new connection: [Errno 111] Connection refused',))
/home/ammadkhalid/projects/python/clients/autobots/google-bank-adder/gbank/core/decorator.py: ERROR    Message:  Screenshot: /home/ammadkhalid/projects/python/clients/autobots/google-bank-adder/logs/screenshots/screenshot_20190105-185013.png
Traceback (most recent call last):
  File "/home/ammadkhalid/projects/python/clients/autobots/google-bank-adder/gbank/core/decorator.py", line 38, in wrap
    return obj(*args, **kwargs)
  File "/home/ammadkhalid/projects/python/clients/autobots/google-bank-adder/gbank/bot/google.py", line 234, in add_bank
    By.ID, path
  File "/home/ammadkhalid/projects/python/me/am-py-bot/venv/lib/python3.6/site-packages/selenium/webdriver/support/wait.py", line 80, in until
    raise TimeoutException(message, screen, stacktrace)
selenium.common.exceptions.TimeoutException: Message:  Screenshot: /home/ammadkhalid/projects/python/clients/autobots/google-bank-adder/logs/screenshots/screenshot_20190105-185013.png

/home/ammadkhalid/projects/python/clients/autobots/google-bank-adder/gbank/core/decorator.py: ERROR    Message: 
Traceback (most recent call last):
  File "/home/ammadkhalid/projects/python/clients/autobots/google-bank-adder/gbank/core/decorator.py", line 93, in wrap
    return func(*args, **kwargs)
  File "/home/ammadkhalid/projects/python/clients/autobots/google-bank-adder/gbank/bot/google.py", line 113, in login
    self._driver.current_url
  File "/home/ammadkhalid/projects/python/me/am-py-bot/venv/lib/python3.6/site-packages/selenium/webdriver/support/wait.py", line 80, in until
    raise TimeoutException(message, screen, stacktrace)
selenium.common.exceptions.TimeoutException: Message: 

c:\users\bilal asghar\music\p\gbank\core\decorator.py: ERROR    [WinError 87] The parameter is incorrect
Traceback (most recent call last):
  File "c:\users\bilal asghar\music\p\gbank\core\decorator.py", line 26, in wrap
    return func(*args, **kwargs)
  File "c:\users\bilal asghar\music\p\gbank\cli\main.py", line 22, in main
    CommandLine().run()
  File "c:\users\bilal asghar\music\p\gbank\cli\main.py", line 14, in run
    self.arg_parser.parse_args()
  File "c:\users\bilal asghar\music\p\gbank\core\argparser.py", line 89, in parse_args
    self._run_program(fun, args)
  File "c:\users\bilal asghar\music\p\gbank\core\argparser.py", line 79, in _run_program
    self._out = fun(**kwargs)
  File "c:\users\bilal asghar\music\p\gbank\cli\google.py", line 14, in main
    driver = Google()
  File "c:\users\bilal asghar\music\p\gbank\bot\google.py", line 21, in __init__
    super().__init__()
  File "c:\users\bilal asghar\music\p\gbank\core\baseselenium.py", line 62, in __init__
    *args, **kwargs)
  File "c:\users\bilal asghar\appdata\local\programs\python\python37-32\lib\site-packages\selenium\webdriver\chrome\webdriver.py", line 73, in __init__
    self.service.start()
  File "c:\users\bilal asghar\appdata\local\programs\python\python37-32\lib\site-packages\selenium\webdriver\common\service.py", line 76, in start
    stdin=PIPE)
  File "c:\users\bilal asghar\appdata\local\programs\python\python37-32\lib\subprocess.py", line 775, in __init__
    restore_signals, start_new_session)
  File "c:\users\bilal asghar\appdata\local\programs\python\python37-32\lib\subprocess.py", line 1178, in _execute_child
    startupinfo)
OSError: [WinError 87] The parameter is incorrect
c:\users\bilal asghar\music\p\gbank\core\decorator.py: ERROR    [WinError 87] The parameter is incorrect
Traceback (most recent call last):
  File "c:\users\bilal asghar\music\p\gbank\core\decorator.py", line 26, in wrap
    return func(*args, **kwargs)
  File "c:\users\bilal asghar\music\p\gbank\cli\main.py", line 22, in main
    CommandLine().run()
  File "c:\users\bilal asghar\music\p\gbank\cli\main.py", line 14, in run
    self.arg_parser.parse_args()
  File "c:\users\bilal asghar\music\p\gbank\core\argparser.py", line 89, in parse_args
    self._run_program(fun, args)
  File "c:\users\bilal asghar\music\p\gbank\core\argparser.py", line 79, in _run_program
    self._out = fun(**kwargs)
  File "c:\users\bilal asghar\music\p\gbank\cli\google.py", line 14, in main
    driver = Google()
  File "c:\users\bilal asghar\music\p\gbank\bot\google.py", line 21, in __init__
    super().__init__()
  File "c:\users\bilal asghar\music\p\gbank\core\baseselenium.py", line 62, in __init__
    *args, **kwargs)
  File "c:\users\bilal asghar\appdata\local\programs\python\python37-32\lib\site-packages\selenium\webdriver\chrome\webdriver.py", line 73, in __init__
    self.service.start()
  File "c:\users\bilal asghar\appdata\local\programs\python\python37-32\lib\site-packages\selenium\webdriver\common\service.py", line 76, in start
    stdin=PIPE)
  File "c:\users\bilal asghar\appdata\local\programs\python\python37-32\lib\subprocess.py", line 775, in __init__
    restore_signals, start_new_session)
  File "c:\users\bilal asghar\appdata\local\programs\python\python37-32\lib\subprocess.py", line 1178, in _execute_child
    startupinfo)
OSError: [WinError 87] The parameter is incorrect
c:\users\bilal asghar\music\p\gbank\core\decorator.py: ERROR    [WinError 87] The parameter is incorrect
Traceback (most recent call last):
  File "c:\users\bilal asghar\music\p\gbank\core\decorator.py", line 26, in wrap
    return func(*args, **kwargs)
  File "c:\users\bilal asghar\music\p\gbank\cli\main.py", line 22, in main
    CommandLine().run()
  File "c:\users\bilal asghar\music\p\gbank\cli\main.py", line 14, in run
    self.arg_parser.parse_args()
  File "c:\users\bilal asghar\music\p\gbank\core\argparser.py", line 89, in parse_args
    self._run_program(fun, args)
  File "c:\users\bilal asghar\music\p\gbank\core\argparser.py", line 79, in _run_program
    self._out = fun(**kwargs)
  File "c:\users\bilal asghar\music\p\gbank\cli\google.py", line 14, in main
    driver = Google()
  File "c:\users\bilal asghar\music\p\gbank\bot\google.py", line 21, in __init__
    super().__init__()
  File "c:\users\bilal asghar\music\p\gbank\core\baseselenium.py", line 62, in __init__
    *args, **kwargs)
  File "c:\users\bilal asghar\appdata\local\programs\python\python37-32\lib\site-packages\selenium\webdriver\chrome\webdriver.py", line 73, in __init__
    self.service.start()
  File "c:\users\bilal asghar\appdata\local\programs\python\python37-32\lib\site-packages\selenium\webdriver\common\service.py", line 76, in start
    stdin=PIPE)
  File "c:\users\bilal asghar\appdata\local\programs\python\python37-32\lib\subprocess.py", line 775, in __init__
    restore_signals, start_new_session)
  File "c:\users\bilal asghar\appdata\local\programs\python\python37-32\lib\subprocess.py", line 1178, in _execute_child
    startupinfo)
OSError: [WinError 87] The parameter is incorrect
c:\users\bilal asghar\music\p\gbank\core\decorator.py: ERROR    Message: session not created: Chrome version must be between 70 and 73
  (Driver info: chromedriver=2.45.615291 (ec3682e3c9061c10f26ea9e5cdcf3c53f3f74387),platform=Windows NT 10.0.17134 x86_64)
Traceback (most recent call last):
  File "c:\users\bilal asghar\music\p\gbank\core\decorator.py", line 26, in wrap
    return func(*args, **kwargs)
  File "c:\users\bilal asghar\music\p\gbank\cli\main.py", line 22, in main
    CommandLine().run()
  File "c:\users\bilal asghar\music\p\gbank\cli\main.py", line 14, in run
    self.arg_parser.parse_args()
  File "c:\users\bilal asghar\music\p\gbank\core\argparser.py", line 89, in parse_args
    self._run_program(fun, args)
  File "c:\users\bilal asghar\music\p\gbank\core\argparser.py", line 79, in _run_program
    self._out = fun(**kwargs)
  File "c:\users\bilal asghar\music\p\gbank\cli\google.py", line 14, in main
    driver = Google()
  File "c:\users\bilal asghar\music\p\gbank\bot\google.py", line 21, in __init__
    super().__init__()
  File "c:\users\bilal asghar\music\p\gbank\core\baseselenium.py", line 62, in __init__
    *args, **kwargs)
  File "c:\users\bilal asghar\appdata\local\programs\python\python37-32\lib\site-packages\selenium\webdriver\chrome\webdriver.py", line 81, in __init__
    desired_capabilities=desired_capabilities)
  File "c:\users\bilal asghar\appdata\local\programs\python\python37-32\lib\site-packages\selenium\webdriver\remote\webdriver.py", line 157, in __init__
    self.start_session(capabilities, browser_profile)
  File "c:\users\bilal asghar\appdata\local\programs\python\python37-32\lib\site-packages\selenium\webdriver\remote\webdriver.py", line 252, in start_session
    response = self.execute(Command.NEW_SESSION, parameters)
  File "c:\users\bilal asghar\appdata\local\programs\python\python37-32\lib\site-packages\selenium\webdriver\remote\webdriver.py", line 321, in execute
    self.error_handler.check_response(response)
  File "c:\users\bilal asghar\appdata\local\programs\python\python37-32\lib\site-packages\selenium\webdriver\remote\errorhandler.py", line 242, in check_response
    raise exception_class(message, screen, stacktrace)
selenium.common.exceptions.SessionNotCreatedException: Message: session not created: Chrome version must be between 70 and 73
  (Driver info: chromedriver=2.45.615291 (ec3682e3c9061c10f26ea9e5cdcf3c53f3f74387),platform=Windows NT 10.0.17134 x86_64)

c:\users\bilal asghar\music\p\gbank\core\decorator.py: ERROR    Message: session not created: Chrome version must be between 70 and 73
  (Driver info: chromedriver=2.45.615291 (ec3682e3c9061c10f26ea9e5cdcf3c53f3f74387),platform=Windows NT 10.0.17134 x86_64)
Traceback (most recent call last):
  File "c:\users\bilal asghar\music\p\gbank\core\decorator.py", line 26, in wrap
    return func(*args, **kwargs)
  File "c:\users\bilal asghar\music\p\gbank\cli\main.py", line 22, in main
    CommandLine().run()
  File "c:\users\bilal asghar\music\p\gbank\cli\main.py", line 14, in run
    self.arg_parser.parse_args()
  File "c:\users\bilal asghar\music\p\gbank\core\argparser.py", line 89, in parse_args
    self._run_program(fun, args)
  File "c:\users\bilal asghar\music\p\gbank\core\argparser.py", line 79, in _run_program
    self._out = fun(**kwargs)
  File "c:\users\bilal asghar\music\p\gbank\cli\google.py", line 14, in main
    driver = Google()
  File "c:\users\bilal asghar\music\p\gbank\bot\google.py", line 21, in __init__
    super().__init__()
  File "c:\users\bilal asghar\music\p\gbank\core\baseselenium.py", line 62, in __init__
    *args, **kwargs)
  File "c:\users\bilal asghar\appdata\local\programs\python\python37-32\lib\site-packages\selenium\webdriver\chrome\webdriver.py", line 81, in __init__
    desired_capabilities=desired_capabilities)
  File "c:\users\bilal asghar\appdata\local\programs\python\python37-32\lib\site-packages\selenium\webdriver\remote\webdriver.py", line 157, in __init__
    self.start_session(capabilities, browser_profile)
  File "c:\users\bilal asghar\appdata\local\programs\python\python37-32\lib\site-packages\selenium\webdriver\remote\webdriver.py", line 252, in start_session
    response = self.execute(Command.NEW_SESSION, parameters)
  File "c:\users\bilal asghar\appdata\local\programs\python\python37-32\lib\site-packages\selenium\webdriver\remote\webdriver.py", line 321, in execute
    self.error_handler.check_response(response)
  File "c:\users\bilal asghar\appdata\local\programs\python\python37-32\lib\site-packages\selenium\webdriver\remote\errorhandler.py", line 242, in check_response
    raise exception_class(message, screen, stacktrace)
selenium.common.exceptions.SessionNotCreatedException: Message: session not created: Chrome version must be between 70 and 73
  (Driver info: chromedriver=2.45.615291 (ec3682e3c9061c10f26ea9e5cdcf3c53f3f74387),platform=Windows NT 10.0.17134 x86_64)

c:\users\bilal asghar\music\p\gbank\core\decorator.py: ERROR    Message: element not interactable
  (Session info: chrome=71.0.3578.98)
  (Driver info: chromedriver=2.45.615291 (ec3682e3c9061c10f26ea9e5cdcf3c53f3f74387),platform=Windows NT 10.0.17134 x86_64) Screenshot: c:\users\bilal asghar\music\p\logs\screenshots\screenshot_20190106-192946.png
Traceback (most recent call last):
  File "c:\users\bilal asghar\music\p\gbank\core\decorator.py", line 38, in wrap
    return obj(*args, **kwargs)
  File "c:\users\bilal asghar\music\p\gbank\bot\google.py", line 177, in add_bank
    self._driver.find_elements_by_class_name('b3id-widget-link')[-1].click()
  File "c:\users\bilal asghar\appdata\local\programs\python\python37-32\lib\site-packages\selenium\webdriver\remote\webelement.py", line 80, in click
    self._execute(Command.CLICK_ELEMENT)
  File "c:\users\bilal asghar\appdata\local\programs\python\python37-32\lib\site-packages\selenium\webdriver\remote\webelement.py", line 633, in _execute
    return self._parent.execute(command, params)
  File "c:\users\bilal asghar\appdata\local\programs\python\python37-32\lib\site-packages\selenium\webdriver\remote\webdriver.py", line 321, in execute
    self.error_handler.check_response(response)
  File "c:\users\bilal asghar\appdata\local\programs\python\python37-32\lib\site-packages\selenium\webdriver\remote\errorhandler.py", line 242, in check_response
    raise exception_class(message, screen, stacktrace)
selenium.common.exceptions.ElementNotVisibleException: Message: element not interactable
  (Session info: chrome=71.0.3578.98)
  (Driver info: chromedriver=2.45.615291 (ec3682e3c9061c10f26ea9e5cdcf3c53f3f74387),platform=Windows NT 10.0.17134 x86_64) Screenshot: c:\users\bilal asghar\music\p\logs\screenshots\screenshot_20190106-192946.png

c:\users\monxu\desktop\google adwords  original\gbank\core\decorator.py: ERROR    Message: chrome not reachable
  (Session info: chrome=71.0.3578.98)
  (Driver info: chromedriver=2.38.552522 (437e6fbedfa8762dec75e2c5b3ddb86763dc9dcb),platform=Windows NT 10.0.17134 x86_64)
Traceback (most recent call last):
  File "c:\users\monxu\desktop\google adwords  original\gbank\core\decorator.py", line 93, in wrap
    return func(*args, **kwargs)
  File "c:\users\monxu\desktop\google adwords  original\gbank\bot\google.py", line 90, in login
    By.ID, btn
  File "c:\users\monxu\appdata\local\programs\python\python37-32\lib\site-packages\selenium\webdriver\support\wait.py", line 71, in until
    value = method(self._driver)
  File "c:\users\monxu\appdata\local\programs\python\python37-32\lib\site-packages\selenium\webdriver\support\expected_conditions.py", line 64, in __call__
    return _find_element(driver, self.locator)
  File "c:\users\monxu\appdata\local\programs\python\python37-32\lib\site-packages\selenium\webdriver\support\expected_conditions.py", line 415, in _find_element
    raise e
  File "c:\users\monxu\appdata\local\programs\python\python37-32\lib\site-packages\selenium\webdriver\support\expected_conditions.py", line 411, in _find_element
    return driver.find_element(*by)
  File "c:\users\monxu\appdata\local\programs\python\python37-32\lib\site-packages\selenium\webdriver\remote\webdriver.py", line 978, in find_element
    'value': value})['value']
  File "c:\users\monxu\appdata\local\programs\python\python37-32\lib\site-packages\selenium\webdriver\remote\webdriver.py", line 321, in execute
    self.error_handler.check_response(response)
  File "c:\users\monxu\appdata\local\programs\python\python37-32\lib\site-packages\selenium\webdriver\remote\errorhandler.py", line 242, in check_response
    raise exception_class(message, screen, stacktrace)
selenium.common.exceptions.WebDriverException: Message: chrome not reachable
  (Session info: chrome=71.0.3578.98)
  (Driver info: chromedriver=2.38.552522 (437e6fbedfa8762dec75e2c5b3ddb86763dc9dcb),platform=Windows NT 10.0.17134 x86_64)

c:\users\monxu\desktop\google adwords  original\gbank\core\decorator.py: ERROR    Message:  Screenshot: c:\users\monxu\desktop\google adwords  original\logs\screenshots\screenshot_20190108-164257.png
Traceback (most recent call last):
  File "c:\users\monxu\desktop\google adwords  original\gbank\core\decorator.py", line 38, in wrap
    return obj(*args, **kwargs)
  File "c:\users\monxu\desktop\google adwords  original\gbank\bot\google.py", line 235, in add_bank
    By.ID, path
  File "c:\users\monxu\appdata\local\programs\python\python37-32\lib\site-packages\selenium\webdriver\support\wait.py", line 80, in until
    raise TimeoutException(message, screen, stacktrace)
selenium.common.exceptions.TimeoutException: Message:  Screenshot: c:\users\monxu\desktop\google adwords  original\logs\screenshots\screenshot_20190108-164257.png

c:\users\monxu\desktop\google adwords  original\gbank\core\decorator.py: ERROR    Message:  Screenshot: c:\users\monxu\desktop\google adwords  original\logs\screenshots\screenshot_20190108-164518.png
Traceback (most recent call last):
  File "c:\users\monxu\desktop\google adwords  original\gbank\core\decorator.py", line 38, in wrap
    return obj(*args, **kwargs)
  File "c:\users\monxu\desktop\google adwords  original\gbank\bot\google.py", line 235, in add_bank
    By.ID, path
  File "c:\users\monxu\appdata\local\programs\python\python37-32\lib\site-packages\selenium\webdriver\support\wait.py", line 80, in until
    raise TimeoutException(message, screen, stacktrace)
selenium.common.exceptions.TimeoutException: Message:  Screenshot: c:\users\monxu\desktop\google adwords  original\logs\screenshots\screenshot_20190108-164518.png

c:\users\monxu\desktop\google adwords  original\gbank\core\decorator.py: ERROR    Message:  Screenshot: c:\users\monxu\desktop\google adwords  original\logs\screenshots\screenshot_20190108-170533.png
Traceback (most recent call last):
  File "c:\users\monxu\desktop\google adwords  original\gbank\core\decorator.py", line 38, in wrap
    return obj(*args, **kwargs)
  File "c:\users\monxu\desktop\google adwords  original\gbank\bot\google.py", line 235, in add_bank
    By.ID, path
  File "c:\users\monxu\appdata\local\programs\python\python37-32\lib\site-packages\selenium\webdriver\support\wait.py", line 80, in until
    raise TimeoutException(message, screen, stacktrace)
selenium.common.exceptions.TimeoutException: Message:  Screenshot: c:\users\monxu\desktop\google adwords  original\logs\screenshots\screenshot_20190108-170533.png

c:\users\monxu\desktop\google adwords  original\gbank\core\decorator.py: ERROR    Message:  Screenshot: c:\users\monxu\desktop\google adwords  original\logs\screenshots\screenshot_20190108-170816.png
Traceback (most recent call last):
  File "c:\users\monxu\desktop\google adwords  original\gbank\core\decorator.py", line 38, in wrap
    return obj(*args, **kwargs)
  File "c:\users\monxu\desktop\google adwords  original\gbank\bot\google.py", line 235, in add_bank
    By.ID, path
  File "c:\users\monxu\appdata\local\programs\python\python37-32\lib\site-packages\selenium\webdriver\support\wait.py", line 80, in until
    raise TimeoutException(message, screen, stacktrace)
selenium.common.exceptions.TimeoutException: Message:  Screenshot: c:\users\monxu\desktop\google adwords  original\logs\screenshots\screenshot_20190108-170816.png

c:\users\monxu\desktop\google adwords  original\gbank\core\decorator.py: ERROR    Message: chrome not reachable
  (Session info: chrome=71.0.3578.98)
  (Driver info: chromedriver=2.38.552522 (437e6fbedfa8762dec75e2c5b3ddb86763dc9dcb),platform=Windows NT 10.0.17134 x86_64)
Traceback (most recent call last):
  File "c:\users\monxu\desktop\google adwords  original\gbank\core\decorator.py", line 93, in wrap
    return func(*args, **kwargs)
  File "c:\users\monxu\desktop\google adwords  original\gbank\bot\google.py", line 90, in login
    By.ID, btn
  File "c:\users\monxu\appdata\local\programs\python\python37-32\lib\site-packages\selenium\webdriver\support\wait.py", line 71, in until
    value = method(self._driver)
  File "c:\users\monxu\appdata\local\programs\python\python37-32\lib\site-packages\selenium\webdriver\support\expected_conditions.py", line 64, in __call__
    return _find_element(driver, self.locator)
  File "c:\users\monxu\appdata\local\programs\python\python37-32\lib\site-packages\selenium\webdriver\support\expected_conditions.py", line 415, in _find_element
    raise e
  File "c:\users\monxu\appdata\local\programs\python\python37-32\lib\site-packages\selenium\webdriver\support\expected_conditions.py", line 411, in _find_element
    return driver.find_element(*by)
  File "c:\users\monxu\appdata\local\programs\python\python37-32\lib\site-packages\selenium\webdriver\remote\webdriver.py", line 978, in find_element
    'value': value})['value']
  File "c:\users\monxu\appdata\local\programs\python\python37-32\lib\site-packages\selenium\webdriver\remote\webdriver.py", line 321, in execute
    self.error_handler.check_response(response)
  File "c:\users\monxu\appdata\local\programs\python\python37-32\lib\site-packages\selenium\webdriver\remote\errorhandler.py", line 242, in check_response
    raise exception_class(message, screen, stacktrace)
selenium.common.exceptions.WebDriverException: Message: chrome not reachable
  (Session info: chrome=71.0.3578.98)
  (Driver info: chromedriver=2.38.552522 (437e6fbedfa8762dec75e2c5b3ddb86763dc9dcb),platform=Windows NT 10.0.17134 x86_64)

c:\users\monxu\desktop\google adwords  original\gbank\core\decorator.py: ERROR    Message: 'chromedriver.exe' executable needs to be in PATH. Please see https://sites.google.com/a/chromium.org/chromedriver/home
Traceback (most recent call last):
  File "c:\users\monxu\appdata\local\programs\python\python37-32\lib\site-packages\selenium\webdriver\common\service.py", line 76, in start
    stdin=PIPE)
  File "c:\users\monxu\appdata\local\programs\python\python37-32\lib\subprocess.py", line 756, in __init__
    restore_signals, start_new_session)
  File "c:\users\monxu\appdata\local\programs\python\python37-32\lib\subprocess.py", line 1155, in _execute_child
    startupinfo)
FileNotFoundError: [WinError 2] El sistema no puede encontrar el archivo especificado

During handling of the above exception, another exception occurred:

Traceback (most recent call last):
  File "c:\users\monxu\desktop\google adwords  original\gbank\core\decorator.py", line 26, in wrap
    return func(*args, **kwargs)
  File "c:\users\monxu\desktop\google adwords  original\gbank\cli\main.py", line 22, in main
    CommandLine().run()
  File "c:\users\monxu\desktop\google adwords  original\gbank\cli\main.py", line 14, in run
    self.arg_parser.parse_args()
  File "c:\users\monxu\desktop\google adwords  original\gbank\core\argparser.py", line 89, in parse_args
    self._run_program(fun, args)
  File "c:\users\monxu\desktop\google adwords  original\gbank\core\argparser.py", line 79, in _run_program
    self._out = fun(**kwargs)
  File "c:\users\monxu\desktop\google adwords  original\gbank\cli\google.py", line 14, in main
    driver = Google()
  File "c:\users\monxu\desktop\google adwords  original\gbank\bot\google.py", line 21, in __init__
    super().__init__()
  File "c:\users\monxu\desktop\google adwords  original\gbank\core\baseselenium.py", line 88, in __init__
    *args, **kwargs)
  File "c:\users\monxu\appdata\local\programs\python\python37-32\lib\site-packages\selenium\webdriver\chrome\webdriver.py", line 73, in __init__
    self.service.start()
  File "c:\users\monxu\appdata\local\programs\python\python37-32\lib\site-packages\selenium\webdriver\common\service.py", line 83, in start
    os.path.basename(self.path), self.start_error_message)
selenium.common.exceptions.WebDriverException: Message: 'chromedriver.exe' executable needs to be in PATH. Please see https://sites.google.com/a/chromium.org/chromedriver/home

c:\users\monxu\desktop\google adwords  original\gbank\core\decorator.py: ERROR    Message: 'chromedriver.exe' executable needs to be in PATH. Please see https://sites.google.com/a/chromium.org/chromedriver/home
Traceback (most recent call last):
  File "c:\users\monxu\appdata\local\programs\python\python37-32\lib\site-packages\selenium\webdriver\common\service.py", line 76, in start
    stdin=PIPE)
  File "c:\users\monxu\appdata\local\programs\python\python37-32\lib\subprocess.py", line 756, in __init__
    restore_signals, start_new_session)
  File "c:\users\monxu\appdata\local\programs\python\python37-32\lib\subprocess.py", line 1155, in _execute_child
    startupinfo)
FileNotFoundError: [WinError 2] El sistema no puede encontrar el archivo especificado

During handling of the above exception, another exception occurred:

Traceback (most recent call last):
  File "c:\users\monxu\desktop\google adwords  original\gbank\core\decorator.py", line 26, in wrap
    return func(*args, **kwargs)
  File "c:\users\monxu\desktop\google adwords  original\gbank\cli\main.py", line 22, in main
    CommandLine().run()
  File "c:\users\monxu\desktop\google adwords  original\gbank\cli\main.py", line 14, in run
    self.arg_parser.parse_args()
  File "c:\users\monxu\desktop\google adwords  original\gbank\core\argparser.py", line 89, in parse_args
    self._run_program(fun, args)
  File "c:\users\monxu\desktop\google adwords  original\gbank\core\argparser.py", line 79, in _run_program
    self._out = fun(**kwargs)
  File "c:\users\monxu\desktop\google adwords  original\gbank\cli\google.py", line 14, in main
    driver = Google()
  File "c:\users\monxu\desktop\google adwords  original\gbank\bot\google.py", line 21, in __init__
    super().__init__()
  File "c:\users\monxu\desktop\google adwords  original\gbank\core\baseselenium.py", line 88, in __init__
    *args, **kwargs)
  File "c:\users\monxu\appdata\local\programs\python\python37-32\lib\site-packages\selenium\webdriver\chrome\webdriver.py", line 73, in __init__
    self.service.start()
  File "c:\users\monxu\appdata\local\programs\python\python37-32\lib\site-packages\selenium\webdriver\common\service.py", line 83, in start
    os.path.basename(self.path), self.start_error_message)
selenium.common.exceptions.WebDriverException: Message: 'chromedriver.exe' executable needs to be in PATH. Please see https://sites.google.com/a/chromium.org/chromedriver/home

c:\users\monxu\desktop\google adwords bo\gbank\core\decorator.py: ERROR    Message: 'chromedriver.exe' executable needs to be in PATH. Please see https://sites.google.com/a/chromium.org/chromedriver/home
Traceback (most recent call last):
  File "c:\users\monxu\appdata\local\programs\python\python37-32\lib\site-packages\selenium\webdriver\common\service.py", line 76, in start
    stdin=PIPE)
  File "c:\users\monxu\appdata\local\programs\python\python37-32\lib\subprocess.py", line 756, in __init__
    restore_signals, start_new_session)
  File "c:\users\monxu\appdata\local\programs\python\python37-32\lib\subprocess.py", line 1155, in _execute_child
    startupinfo)
FileNotFoundError: [WinError 2] El sistema no puede encontrar el archivo especificado

During handling of the above exception, another exception occurred:

Traceback (most recent call last):
  File "c:\users\monxu\desktop\google adwords bo\gbank\core\decorator.py", line 26, in wrap
    return func(*args, **kwargs)
  File "c:\users\monxu\desktop\google adwords bo\gbank\cli\main.py", line 22, in main
    CommandLine().run()
  File "c:\users\monxu\desktop\google adwords bo\gbank\cli\main.py", line 14, in run
    self.arg_parser.parse_args()
  File "c:\users\monxu\desktop\google adwords bo\gbank\core\argparser.py", line 89, in parse_args
    self._run_program(fun, args)
  File "c:\users\monxu\desktop\google adwords bo\gbank\core\argparser.py", line 79, in _run_program
    self._out = fun(**kwargs)
  File "c:\users\monxu\desktop\google adwords bo\gbank\cli\google.py", line 14, in main
    driver = Google()
  File "c:\users\monxu\desktop\google adwords bo\gbank\bot\google.py", line 21, in __init__
    super().__init__()
  File "c:\users\monxu\desktop\google adwords bo\gbank\core\baseselenium.py", line 88, in __init__
    *args, **kwargs)
  File "c:\users\monxu\appdata\local\programs\python\python37-32\lib\site-packages\selenium\webdriver\chrome\webdriver.py", line 73, in __init__
    self.service.start()
  File "c:\users\monxu\appdata\local\programs\python\python37-32\lib\site-packages\selenium\webdriver\common\service.py", line 83, in start
    os.path.basename(self.path), self.start_error_message)
selenium.common.exceptions.WebDriverException: Message: 'chromedriver.exe' executable needs to be in PATH. Please see https://sites.google.com/a/chromium.org/chromedriver/home

c:\users\monxu\desktop\google adwords bo\gbank\core\decorator.py: ERROR    Message: 'chromedriver.exe' executable needs to be in PATH. Please see https://sites.google.com/a/chromium.org/chromedriver/home
Traceback (most recent call last):
  File "c:\users\monxu\appdata\local\programs\python\python37-32\lib\site-packages\selenium\webdriver\common\service.py", line 76, in start
    stdin=PIPE)
  File "c:\users\monxu\appdata\local\programs\python\python37-32\lib\subprocess.py", line 756, in __init__
    restore_signals, start_new_session)
  File "c:\users\monxu\appdata\local\programs\python\python37-32\lib\subprocess.py", line 1155, in _execute_child
    startupinfo)
FileNotFoundError: [WinError 2] El sistema no puede encontrar el archivo especificado

During handling of the above exception, another exception occurred:

Traceback (most recent call last):
  File "c:\users\monxu\desktop\google adwords bo\gbank\core\decorator.py", line 26, in wrap
    return func(*args, **kwargs)
  File "c:\users\monxu\desktop\google adwords bo\gbank\cli\main.py", line 22, in main
    CommandLine().run()
  File "c:\users\monxu\desktop\google adwords bo\gbank\cli\main.py", line 14, in run
    self.arg_parser.parse_args()
  File "c:\users\monxu\desktop\google adwords bo\gbank\core\argparser.py", line 89, in parse_args
    self._run_program(fun, args)
  File "c:\users\monxu\desktop\google adwords bo\gbank\core\argparser.py", line 79, in _run_program
    self._out = fun(**kwargs)
  File "c:\users\monxu\desktop\google adwords bo\gbank\cli\google.py", line 14, in main
    driver = Google()
  File "c:\users\monxu\desktop\google adwords bo\gbank\bot\google.py", line 21, in __init__
    super().__init__()
  File "c:\users\monxu\desktop\google adwords bo\gbank\core\baseselenium.py", line 88, in __init__
    *args, **kwargs)
  File "c:\users\monxu\appdata\local\programs\python\python37-32\lib\site-packages\selenium\webdriver\chrome\webdriver.py", line 73, in __init__
    self.service.start()
  File "c:\users\monxu\appdata\local\programs\python\python37-32\lib\site-packages\selenium\webdriver\common\service.py", line 83, in start
    os.path.basename(self.path), self.start_error_message)
selenium.common.exceptions.WebDriverException: Message: 'chromedriver.exe' executable needs to be in PATH. Please see https://sites.google.com/a/chromium.org/chromedriver/home

c:\users\monxu\desktop\google adwords bo\gbank\core\decorator.py: ERROR    Message: 'chromedriver.exe' executable needs to be in PATH. Please see https://sites.google.com/a/chromium.org/chromedriver/home
Traceback (most recent call last):
  File "c:\users\monxu\appdata\local\programs\python\python37-32\lib\site-packages\selenium\webdriver\common\service.py", line 76, in start
    stdin=PIPE)
  File "c:\users\monxu\appdata\local\programs\python\python37-32\lib\subprocess.py", line 756, in __init__
    restore_signals, start_new_session)
  File "c:\users\monxu\appdata\local\programs\python\python37-32\lib\subprocess.py", line 1155, in _execute_child
    startupinfo)
FileNotFoundError: [WinError 2] El sistema no puede encontrar el archivo especificado

During handling of the above exception, another exception occurred:

Traceback (most recent call last):
  File "c:\users\monxu\desktop\google adwords bo\gbank\core\decorator.py", line 26, in wrap
    return func(*args, **kwargs)
  File "c:\users\monxu\desktop\google adwords bo\gbank\cli\main.py", line 22, in main
    CommandLine().run()
  File "c:\users\monxu\desktop\google adwords bo\gbank\cli\main.py", line 14, in run
    self.arg_parser.parse_args()
  File "c:\users\monxu\desktop\google adwords bo\gbank\core\argparser.py", line 89, in parse_args
    self._run_program(fun, args)
  File "c:\users\monxu\desktop\google adwords bo\gbank\core\argparser.py", line 79, in _run_program
    self._out = fun(**kwargs)
  File "c:\users\monxu\desktop\google adwords bo\gbank\cli\google.py", line 14, in main
    driver = Google()
  File "c:\users\monxu\desktop\google adwords bo\gbank\bot\google.py", line 21, in __init__
    super().__init__()
  File "c:\users\monxu\desktop\google adwords bo\gbank\core\baseselenium.py", line 88, in __init__
    *args, **kwargs)
  File "c:\users\monxu\appdata\local\programs\python\python37-32\lib\site-packages\selenium\webdriver\chrome\webdriver.py", line 73, in __init__
    self.service.start()
  File "c:\users\monxu\appdata\local\programs\python\python37-32\lib\site-packages\selenium\webdriver\common\service.py", line 83, in start
    os.path.basename(self.path), self.start_error_message)
selenium.common.exceptions.WebDriverException: Message: 'chromedriver.exe' executable needs to be in PATH. Please see https://sites.google.com/a/chromium.org/chromedriver/home

